Workbook

Sheet Principal
A1: Bases | B1: Metodos | C1: Resultados F1-Score | O1: Bases a serem usadas
C2: Knn1 | D2: Knn2 | E2: Knn3 | F2: Knn4 | G2: Knn5 | H2: Knn6 | I2: Knn7 | J2: Knn8 | K2: Knn9 | L2: Knn10
A3: HOG_128_16x16.csv | B3: 70/30 | C3: =IFERROR(VLOOKUP($A3&C$2&$B3,Dados7030!$E$1:$F$360,2,FALSE), VLOOKUP($A3&C$2&$B3,Dados10Fold!$E$1:$F$360,2,FALSE)) -> 0.5821 | D3: =IFERROR(VLOOKUP($A3&D$2&$B3,Dados7030!$E$1:$F$360,2,FALSE), VLOOKUP($A3&D$2&$B3,Dados10Fold!$E$1:$F$360,2,FALSE)) -> 0.6258 | E3: =IFERROR(VLOOKUP($A3&E$2&$B3,Dados7030!$E$1:$F$360,2,FALSE), VLOOKUP($A3&E$2&$B3,Dados10Fold!$E$1:$F$360,2,FALSE)) -> 0.5479 | F3: =IFERROR(VLOOKUP($A3&F$2&$B3,Dados7030!$E$1:$F$360,2,FALSE), VLOOKUP($A3&F$2&$B3,Dados10Fold!$E$1:$F$360,2,FALSE)) -> 0.5978 | G3: =IFERROR(VLOOKUP($A3&G$2&$B3,Dados7030!$E$1:$F$360,2,FALSE), VLOOKUP($A3&G$2&$B3,Dados10Fold!$E$1:$F$360,2,FALSE)) -> 0.542 | H3: =IFERROR(VLOOKUP($A3&H$2&$B3,Dados7030!$E$1:$F$360,2,FALSE), VLOOKUP($A3&H$2&$B3,Dados10Fold!$E$1:$F$360,2,FALSE)) -> 0.574 | I3: =IFERROR(VLOOKUP($A3&I$2&$B3,Dados7030!$E$1:$F$360,2,FALSE), VLOOKUP($A3&I$2&$B3,Dados10Fold!$E$1:$F$360,2,FALSE)) -> 0.5133 | J3: =IFERROR(VLOOKUP($A3&J$2&$B3,Dados7030!$E$1:$F$360,2,FALSE), VLOOKUP($A3&J$2&$B3,Dados10Fold!$E$1:$F$360,2,FALSE)) -> 0.553 | ... L3: =IFERROR(VLOOKUP($A3&L$2&$B3,Dados7030!$E$1:$F$360,2,FALSE), VLOOKUP($A3&L$2&$B3,Dados10Fold!$E$1:$F$360,2,FALSE)) -> 0.5336 | M3: =MEDIAN(C3:L4) -> 0.55635 | O3: HOG_128_16x16_PCA75.csv
B4: 10Fold | C4: =IFERROR(VLOOKUP($A3&C$2&$B4,Dados7030!$E$1:$F$360,2,FALSE), VLOOKUP($A3&C$2&$B4,Dados10Fold!$E$1:$F$360,2,FALSE)) -> 0.5824 | D4: =IFERROR(VLOOKUP($A3&D$2&$B4,Dados7030!$E$1:$F$360,2,FALSE), VLOOKUP($A3&D$2&$B4,Dados10Fold!$E$1:$F$360,2,FALSE)) -> 0.6199 | E4: =IFERROR(VLOOKUP($A3&E$2&$B4,Dados7030!$E$1:$F$360,2,FALSE), VLOOKUP($A3&E$2&$B4,Dados10Fold!$E$1:$F$360,2,FALSE)) -> 0.5597 | F4: =IFERROR(VLOOKUP($A3&F$2&$B4,Dados7030!$E$1:$F$360,2,FALSE), VLOOKUP($A3&F$2&$B4,Dados10Fold!$E$1:$F$360,2,FALSE)) -> 0.6059 | G4: =IFERROR(VLOOKUP($A3&G$2&$B4,Dados7030!$E$1:$F$360,2,FALSE), VLOOKUP($A3&G$2&$B4,Dados10Fold!$E$1:$F$360,2,FALSE)) -> 0.5399 | H4: =IFERROR(VLOOKUP($A3&H$2&$B4,Dados7030!$E$1:$F$360,2,FALSE), VLOOKUP($A3&H$2&$B4,Dados10Fold!$E$1:$F$360,2,FALSE)) -> 0.5847 | I4: =IFERROR(VLOOKUP($A3&I$2&$B4,Dados7030!$E$1:$F$360,2,FALSE), VLOOKUP($A3&I$2&$B4,Dados10Fold!$E$1:$F$360,2,FALSE)) -> 0.5236 | J4: =IFERROR(VLOOKUP($A3&J$2&$B4,Dados7030!$E$1:$F$360,2,FALSE), VLOOKUP($A3&J$2&$B4,Dados10Fold!$E$1:$F$360,2,FALSE)) -> 0.5621 | ... L4: =IFERROR(VLOOKUP($A3&L$2&$B4,Dados7030!$E$1:$F$360,2,FALSE), VLOOKUP($A3&L$2&$B4,Dados10Fold!$E$1:$F$360,2,FALSE)) -> 0.5432
A5: HOG_128_16x16_PCA75.csv | B5: 70/30 | C5: =IFERROR(VLOOKUP($A5&C$2&$B5,Dados7030!$E$1:$F$360,2,FALSE), VLOOKUP($A5&C$2&$B5,Dados10Fold!$E$1:$F$360,2,FALSE)) -> 0.6202 | D5: =IFERROR(VLOOKUP($A5&D$2&$B5,Dados7030!$E$1:$F$360,2,FALSE), VLOOKUP($A5&D$2&$B5,Dados10Fold!$E$1:$F$360,2,FALSE)) -> 0.6631 | E5: =IFERROR(VLOOKUP($A5&E$2&$B5,Dados7030!$E$1:$F$360,2,FALSE), VLOOKUP($A5&E$2&$B5,Dados10Fold!$E$1:$F$360,2,FALSE)) -> 0.6126 | F5: =IFERROR(VLOOKUP($A5&F$2&$B5,Dados7030!$E$1:$F$360,2,FALSE), VLOOKUP($A5&F$2&$B5,Dados10Fold!$E$1:$F$360,2,FALSE)) -> 0.6476 | G5: =IFERROR(VLOOKUP($A5&G$2&$B5,Dados7030!$E$1:$F$360,2,FALSE), VLOOKUP($A5&G$2&$B5,Dados10Fold!$E$1:$F$360,2,FALSE)) -> 0.5922 | H5: =IFERROR(VLOOKUP($A5&H$2&$B5,Dados7030!$E$1:$F$360,2,FALSE), VLOOKUP($A5&H$2&$B5,Dados10Fold!$E$1:$F$360,2,FALSE)) -> 0.631 | I5: =IFERROR(VLOOKUP($A5&I$2&$B5,Dados7030!$E$1:$F$360,2,FALSE), VLOOKUP($A5&I$2&$B5,Dados10Fold!$E$1:$F$360,2,FALSE)) -> 0.592 | J5: =IFERROR(VLOOKUP($A5&J$2&$B5,Dados7030!$E$1:$F$360,2,FALSE), VLOOKUP($A5&J$2&$B5,Dados10Fold!$E$1:$F$360,2,FALSE)) -> 0.6242 | ... L5: =IFERROR(VLOOKUP($A5&L$2&$B5,Dados7030!$E$1:$F$360,2,FALSE), VLOOKUP($A5&L$2&$B5,Dados10Fold!$E$1:$F$360,2,FALSE)) -> 0.5993 | M5: =MEDIAN(C5:L6) -> 0.6195 | O5: HOG_128_32x32.csv
B6: 10Fold | C6: =IFERROR(VLOOKUP($A5&C$2&$B6,Dados7030!$E$1:$F$360,2,FALSE), VLOOKUP($A5&C$2&$B6,Dados10Fold!$E$1:$F$360,2,FALSE)) -> 0.6453 | D6: =IFERROR(VLOOKUP($A5&D$2&$B6,Dados7030!$E$1:$F$360,2,FALSE), VLOOKUP($A5&D$2&$B6,Dados10Fold!$E$1:$F$360,2,FALSE)) -> 0.6743 | E6: =IFERROR(VLOOKUP($A5&E$2&$B6,Dados7030!$E$1:$F$360,2,FALSE), VLOOKUP($A5&E$2&$B6,Dados10Fold!$E$1:$F$360,2,FALSE)) -> 0.6188 | F6: =IFERROR(VLOOKUP($A5&F$2&$B6,Dados7030!$E$1:$F$360,2,FALSE), VLOOKUP($A5&F$2&$B6,Dados10Fold!$E$1:$F$360,2,FALSE)) -> 0.6535 | G6: =IFERROR(VLOOKUP($A5&G$2&$B6,Dados7030!$E$1:$F$360,2,FALSE), VLOOKUP($A5&G$2&$B6,Dados10Fold!$E$1:$F$360,2,FALSE)) -> 0.6086 | H6: =IFERROR(VLOOKUP($A5&H$2&$B6,Dados7030!$E$1:$F$360,2,FALSE), VLOOKUP($A5&H$2&$B6,Dados10Fold!$E$1:$F$360,2,FALSE)) -> 0.6367 | I6: =IFERROR(VLOOKUP($A5&I$2&$B6,Dados7030!$E$1:$F$360,2,FALSE), VLOOKUP($A5&I$2&$B6,Dados10Fold!$E$1:$F$360,2,FALSE)) -> 0.5964 | J6: =IFERROR(VLOOKUP($A5&J$2&$B6,Dados7030!$E$1:$F$360,2,FALSE), VLOOKUP($A5&J$2&$B6,Dados10Fold!$E$1:$F$360,2,FALSE)) -> 0.6294 | ... L6: =IFERROR(VLOOKUP($A5&L$2&$B6,Dados7030!$E$1:$F$360,2,FALSE), VLOOKUP($A5&L$2&$B6,Dados10Fold!$E$1:$F$360,2,FALSE)) -> 0.6159
A7: HOG_128_16x16_PCA90.csv | B7: 70/30 | C7: =IFERROR(VLOOKUP($A7&C$2&$B7,Dados7030!$E$1:$F$360,2,FALSE), VLOOKUP($A7&C$2&$B7,Dados10Fold!$E$1:$F$360,2,FALSE)) -> 0.5696 | D7: =IFERROR(VLOOKUP($A7&D$2&$B7,Dados7030!$E$1:$F$360,2,FALSE), VLOOKUP($A7&D$2&$B7,Dados10Fold!$E$1:$F$360,2,FALSE)) -> 0.6255 | E7: =IFERROR(VLOOKUP($A7&E$2&$B7,Dados7030!$E$1:$F$360,2,FALSE), VLOOKUP($A7&E$2&$B7,Dados10Fold!$E$1:$F$360,2,FALSE)) -> 0.5657 | F7: =IFERROR(VLOOKUP($A7&F$2&$B7,Dados7030!$E$1:$F$360,2,FALSE), VLOOKUP($A7&F$2&$B7,Dados10Fold!$E$1:$F$360,2,FALSE)) -> 0.6132 | G7: =IFERROR(VLOOKUP($A7&G$2&$B7,Dados7030!$E$1:$F$360,2,FALSE), VLOOKUP($A7&G$2&$B7,Dados10Fold!$E$1:$F$360,2,FALSE)) -> 0.5533 | H7: =IFERROR(VLOOKUP($A7&H$2&$B7,Dados7030!$E$1:$F$360,2,FALSE), VLOOKUP($A7&H$2&$B7,Dados10Fold!$E$1:$F$360,2,FALSE)) -> 0.5941 | I7: =IFERROR(VLOOKUP($A7&I$2&$B7,Dados7030!$E$1:$F$360,2,FALSE), VLOOKUP($A7&I$2&$B7,Dados10Fold!$E$1:$F$360,2,FALSE)) -> 0.5405 | J7: =IFERROR(VLOOKUP($A7&J$2&$B7,Dados7030!$E$1:$F$360,2,FALSE), VLOOKUP($A7&J$2&$B7,Dados10Fold!$E$1:$F$360,2,FALSE)) -> 0.5922 | ... L7: =IFERROR(VLOOKUP($A7&L$2&$B7,Dados7030!$E$1:$F$360,2,FALSE), VLOOKUP($A7&L$2&$B7,Dados10Fold!$E$1:$F$360,2,FALSE)) -> 0.5694 | M7: =MEDIAN(C7:L8) -> 0.57335 | O7: HOG_128_32x32_PCA75.csv
B8: 10Fold | C8: =IFERROR(VLOOKUP($A7&C$2&$B8,Dados7030!$E$1:$F$360,2,FALSE), VLOOKUP($A7&C$2&$B8,Dados10Fold!$E$1:$F$360,2,FALSE)) -> 0.6007 | D8: =IFERROR(VLOOKUP($A7&D$2&$B8,Dados7030!$E$1:$F$360,2,FALSE), VLOOKUP($A7&D$2&$B8,Dados10Fold!$E$1:$F$360,2,FALSE)) -> 0.6372 | E8: =IFERROR(VLOOKUP($A7&E$2&$B8,Dados7030!$E$1:$F$360,2,FALSE), VLOOKUP($A7&E$2&$B8,Dados10Fold!$E$1:$F$360,2,FALSE)) -> 0.5763 | F8: =IFERROR(VLOOKUP($A7&F$2&$B8,Dados7030!$E$1:$F$360,2,FALSE), VLOOKUP($A7&F$2&$B8,Dados10Fold!$E$1:$F$360,2,FALSE)) -> 0.6155 | G8: =IFERROR(VLOOKUP($A7&G$2&$B8,Dados7030!$E$1:$F$360,2,FALSE), VLOOKUP($A7&G$2&$B8,Dados10Fold!$E$1:$F$360,2,FALSE)) -> 0.5596 | H8: =IFERROR(VLOOKUP($A7&H$2&$B8,Dados7030!$E$1:$F$360,2,FALSE), VLOOKUP($A7&H$2&$B8,Dados10Fold!$E$1:$F$360,2,FALSE)) -> 0.6037 | I8: =IFERROR(VLOOKUP($A7&I$2&$B8,Dados7030!$E$1:$F$360,2,FALSE), VLOOKUP($A7&I$2&$B8,Dados10Fold!$E$1:$F$360,2,FALSE)) -> 0.5434 | J8: =IFERROR(VLOOKUP($A7&J$2&$B8,Dados7030!$E$1:$F$360,2,FALSE), VLOOKUP($A7&J$2&$B8,Dados10Fold!$E$1:$F$360,2,FALSE)) -> 0.5847 | ... L8: =IFERROR(VLOOKUP($A7&L$2&$B8,Dados7030!$E$1:$F$360,2,FALSE), VLOOKUP($A7&L$2&$B8,Dados10Fold!$E$1:$F$360,2,FALSE)) -> 0.5704
A9: HOG_128_32x32.csv | B9: 70/30 | C9: =IFERROR(VLOOKUP($A9&C$2&$B9,Dados7030!$E$1:$F$360,2,FALSE), VLOOKUP($A9&C$2&$B9,Dados10Fold!$E$1:$F$360,2,FALSE)) -> 0.6448 | D9: =IFERROR(VLOOKUP($A9&D$2&$B9,Dados7030!$E$1:$F$360,2,FALSE), VLOOKUP($A9&D$2&$B9,Dados10Fold!$E$1:$F$360,2,FALSE)) -> 0.6636 | E9: =IFERROR(VLOOKUP($A9&E$2&$B9,Dados7030!$E$1:$F$360,2,FALSE), VLOOKUP($A9&E$2&$B9,Dados10Fold!$E$1:$F$360,2,FALSE)) -> 0.6268 | F9: =IFERROR(VLOOKUP($A9&F$2&$B9,Dados7030!$E$1:$F$360,2,FALSE), VLOOKUP($A9&F$2&$B9,Dados10Fold!$E$1:$F$360,2,FALSE)) -> 0.6673 | G9: =IFERROR(VLOOKUP($A9&G$2&$B9,Dados7030!$E$1:$F$360,2,FALSE), VLOOKUP($A9&G$2&$B9,Dados10Fold!$E$1:$F$360,2,FALSE)) -> 0.6236 | H9: =IFERROR(VLOOKUP($A9&H$2&$B9,Dados7030!$E$1:$F$360,2,FALSE), VLOOKUP($A9&H$2&$B9,Dados10Fold!$E$1:$F$360,2,FALSE)) -> 0.6634 | I9: =IFERROR(VLOOKUP($A9&I$2&$B9,Dados7030!$E$1:$F$360,2,FALSE), VLOOKUP($A9&I$2&$B9,Dados10Fold!$E$1:$F$360,2,FALSE)) -> 0.6186 | J9: =IFERROR(VLOOKUP($A9&J$2&$B9,Dados7030!$E$1:$F$360,2,FALSE), VLOOKUP($A9&J$2&$B9,Dados10Fold!$E$1:$F$360,2,FALSE)) -> 0.6569 | ... L9: =IFERROR(VLOOKUP($A9&L$2&$B9,Dados7030!$E$1:$F$360,2,FALSE), VLOOKUP($A9&L$2&$B9,Dados10Fold!$E$1:$F$360,2,FALSE)) -> 0.6434 | M9: =MEDIAN(C9:L10) -> 0.64135 | O9: HOG_128_32x32_PCA90.csv
B10: 10Fold | C10: =IFERROR(VLOOKUP($A9&C$2&$B10,Dados7030!$E$1:$F$360,2,FALSE), VLOOKUP($A9&C$2&$B10,Dados10Fold!$E$1:$F$360,2,FALSE)) -> 0.6374 | D10: =IFERROR(VLOOKUP($A9&D$2&$B10,Dados7030!$E$1:$F$360,2,FALSE), VLOOKUP($A9&D$2&$B10,Dados10Fold!$E$1:$F$360,2,FALSE)) -> 0.6714 | E10: =IFERROR(VLOOKUP($A9&E$2&$B10,Dados7030!$E$1:$F$360,2,FALSE), VLOOKUP($A9&E$2&$B10,Dados10Fold!$E$1:$F$360,2,FALSE)) -> 0.6356 | F10: =IFERROR(VLOOKUP($A9&F$2&$B10,Dados7030!$E$1:$F$360,2,FALSE), VLOOKUP($A9&F$2&$B10,Dados10Fold!$E$1:$F$360,2,FALSE)) -> 0.6729 | G10: =IFERROR(VLOOKUP($A9&G$2&$B10,Dados7030!$E$1:$F$360,2,FALSE), VLOOKUP($A9&G$2&$B10,Dados10Fold!$E$1:$F$360,2,FALSE)) -> 0.6281 | H10: =IFERROR(VLOOKUP($A9&H$2&$B10,Dados7030!$E$1:$F$360,2,FALSE), VLOOKUP($A9&H$2&$B10,Dados10Fold!$E$1:$F$360,2,FALSE)) -> 0.6586 | I10: =IFERROR(VLOOKUP($A9&I$2&$B10,Dados7030!$E$1:$F$360,2,FALSE), VLOOKUP($A9&I$2&$B10,Dados10Fold!$E$1:$F$360,2,FALSE)) -> 0.6147 | J10: =IFERROR(VLOOKUP($A9&J$2&$B10,Dados7030!$E$1:$F$360,2,FALSE), VLOOKUP($A9&J$2&$B10,Dados10Fold!$E$1:$F$360,2,FALSE)) -> 0.6485 | ... L10: =IFERROR(VLOOKUP($A9&L$2&$B10,Dados7030!$E$1:$F$360,2,FALSE), VLOOKUP($A9&L$2&$B10,Dados10Fold!$E$1:$F$360,2,FALSE)) -> 0.6393
A11: HOG_128_32x32_PCA75.csv | B11: 70/30 | C11: =IFERROR(VLOOKUP($A11&C$2&$B11,Dados7030!$E$1:$F$360,2,FALSE), VLOOKUP($A11&C$2&$B11,Dados10Fold!$E$1:$F$360,2,FALSE)) -> 0.6502 | D11: =IFERROR(VLOOKUP($A11&D$2&$B11,Dados7030!$E$1:$F$360,2,FALSE), VLOOKUP($A11&D$2&$B11,Dados10Fold!$E$1:$F$360,2,FALSE)) -> 0.6771 | E11: =IFERROR(VLOOKUP($A11&E$2&$B11,Dados7030!$E$1:$F$360,2,FALSE), VLOOKUP($A11&E$2&$B11,Dados10Fold!$E$1:$F$360,2,FALSE)) -> 0.6666 | F11: =IFERROR(VLOOKUP($A11&F$2&$B11,Dados7030!$E$1:$F$360,2,FALSE), VLOOKUP($A11&F$2&$B11,Dados10Fold!$E$1:$F$360,2,FALSE)) -> 0.6942 | G11: =IFERROR(VLOOKUP($A11&G$2&$B11,Dados7030!$E$1:$F$360,2,FALSE), VLOOKUP($A11&G$2&$B11,Dados10Fold!$E$1:$F$360,2,FALSE)) -> 0.6751 | H11: =IFERROR(VLOOKUP($A11&H$2&$B11,Dados7030!$E$1:$F$360,2,FALSE), VLOOKUP($A11&H$2&$B11,Dados10Fold!$E$1:$F$360,2,FALSE)) -> 0.7032 | I11: =IFERROR(VLOOKUP($A11&I$2&$B11,Dados7030!$E$1:$F$360,2,FALSE), VLOOKUP($A11&I$2&$B11,Dados10Fold!$E$1:$F$360,2,FALSE)) -> 0.6776 | J11: =IFERROR(VLOOKUP($A11&J$2&$B11,Dados7030!$E$1:$F$360,2,FALSE), VLOOKUP($A11&J$2&$B11,Dados10Fold!$E$1:$F$360,2,FALSE)) -> 0.7051 | ... L11: =IFERROR(VLOOKUP($A11&L$2&$B11,Dados7030!$E$1:$F$360,2,FALSE), VLOOKUP($A11&L$2&$B11,Dados10Fold!$E$1:$F$360,2,FALSE)) -> 0.7029 | M11: =MEDIAN(C11:L12) -> 0.67735 | O11: HOG_256_32x32_PCA75.csv
B12: 10Fold | C12: =IFERROR(VLOOKUP($A11&C$2&$B12,Dados7030!$E$1:$F$360,2,FALSE), VLOOKUP($A11&C$2&$B12,Dados10Fold!$E$1:$F$360,2,FALSE)) -> 0.6549 | D12: =IFERROR(VLOOKUP($A11&D$2&$B12,Dados7030!$E$1:$F$360,2,FALSE), VLOOKUP($A11&D$2&$B12,Dados10Fold!$E$1:$F$360,2,FALSE)) -> 0.671 | E12: =IFERROR(VLOOKUP($A11&E$2&$B12,Dados7030!$E$1:$F$360,2,FALSE), VLOOKUP($A11&E$2&$B12,Dados10Fold!$E$1:$F$360,2,FALSE)) -> 0.6648 | F12: =IFERROR(VLOOKUP($A11&F$2&$B12,Dados7030!$E$1:$F$360,2,FALSE), VLOOKUP($A11&F$2&$B12,Dados10Fold!$E$1:$F$360,2,FALSE)) -> 0.6973 | G12: =IFERROR(VLOOKUP($A11&G$2&$B12,Dados7030!$E$1:$F$360,2,FALSE), VLOOKUP($A11&G$2&$B12,Dados10Fold!$E$1:$F$360,2,FALSE)) -> 0.6738 | H12: =IFERROR(VLOOKUP($A11&H$2&$B12,Dados7030!$E$1:$F$360,2,FALSE), VLOOKUP($A11&H$2&$B12,Dados10Fold!$E$1:$F$360,2,FALSE)) -> 0.698 | I12: =IFERROR(VLOOKUP($A11&I$2&$B12,Dados7030!$E$1:$F$360,2,FALSE), VLOOKUP($A11&I$2&$B12,Dados10Fold!$E$1:$F$360,2,FALSE)) -> 0.6718 | J12: =IFERROR(VLOOKUP($A11&J$2&$B12,Dados7030!$E$1:$F$360,2,FALSE), VLOOKUP($A11&J$2&$B12,Dados10Fold!$E$1:$F$360,2,FALSE)) -> 0.6958 | ... L12: =IFERROR(VLOOKUP($A11&L$2&$B12,Dados7030!$E$1:$F$360,2,FALSE), VLOOKUP($A11&L$2&$B12,Dados10Fold!$E$1:$F$360,2,FALSE)) -> 0.7017
A13: HOG_128_32x32_PCA90.csv | B13: 70/30 | C13: =IFERROR(VLOOKUP($A13&C$2&$B13,Dados7030!$E$1:$F$360,2,FALSE), VLOOKUP($A13&C$2&$B13,Dados10Fold!$E$1:$F$360,2,FALSE)) -> 0.6505 | D13: =IFERROR(VLOOKUP($A13&D$2&$B13,Dados7030!$E$1:$F$360,2,FALSE), VLOOKUP($A13&D$2&$B13,Dados10Fold!$E$1:$F$360,2,FALSE)) -> 0.6782 | E13: =IFERROR(VLOOKUP($A13&E$2&$B13,Dados7030!$E$1:$F$360,2,FALSE), VLOOKUP($A13&E$2&$B13,Dados10Fold!$E$1:$F$360,2,FALSE)) -> 0.6655 | F13: =IFERROR(VLOOKUP($A13&F$2&$B13,Dados7030!$E$1:$F$360,2,FALSE), VLOOKUP($A13&F$2&$B13,Dados10Fold!$E$1:$F$360,2,FALSE)) -> 0.7 | G13: =IFERROR(VLOOKUP($A13&G$2&$B13,Dados7030!$E$1:$F$360,2,FALSE), VLOOKUP($A13&G$2&$B13,Dados10Fold!$E$1:$F$360,2,FALSE)) -> 0.6604 | H13: =IFERROR(VLOOKUP($A13&H$2&$B13,Dados7030!$E$1:$F$360,2,FALSE), VLOOKUP($A13&H$2&$B13,Dados10Fold!$E$1:$F$360,2,FALSE)) -> 0.6937 | I13: =IFERROR(VLOOKUP($A13&I$2&$B13,Dados7030!$E$1:$F$360,2,FALSE), VLOOKUP($A13&I$2&$B13,Dados10Fold!$E$1:$F$360,2,FALSE)) -> 0.6498 | J13: =IFERROR(VLOOKUP($A13&J$2&$B13,Dados7030!$E$1:$F$360,2,FALSE), VLOOKUP($A13&J$2&$B13,Dados10Fold!$E$1:$F$360,2,FALSE)) -> 0.6934 | ... L13: =IFERROR(VLOOKUP($A13&L$2&$B13,Dados7030!$E$1:$F$360,2,FALSE), VLOOKUP($A13&L$2&$B13,Dados10Fold!$E$1:$F$360,2,FALSE)) -> 0.6792 | M13: =MEDIAN(C13:L14) -> 0.66755 | O13: HOG_256_32x32_PCA90.csv
B14: 10Fold | C14: =IFERROR(VLOOKUP($A13&C$2&$B14,Dados7030!$E$1:$F$360,2,FALSE), VLOOKUP($A13&C$2&$B14,Dados10Fold!$E$1:$F$360,2,FALSE)) -> 0.6445 | D14: =IFERROR(VLOOKUP($A13&D$2&$B14,Dados7030!$E$1:$F$360,2,FALSE), VLOOKUP($A13&D$2&$B14,Dados10Fold!$E$1:$F$360,2,FALSE)) -> 0.6777 | E14: =IFERROR(VLOOKUP($A13&E$2&$B14,Dados7030!$E$1:$F$360,2,FALSE), VLOOKUP($A13&E$2&$B14,Dados10Fold!$E$1:$F$360,2,FALSE)) -> 0.6436 | F14: =IFERROR(VLOOKUP($A13&F$2&$B14,Dados7030!$E$1:$F$360,2,FALSE), VLOOKUP($A13&F$2&$B14,Dados10Fold!$E$1:$F$360,2,FALSE)) -> 0.6873 | G14: =IFERROR(VLOOKUP($A13&G$2&$B14,Dados7030!$E$1:$F$360,2,FALSE), VLOOKUP($A13&G$2&$B14,Dados10Fold!$E$1:$F$360,2,FALSE)) -> 0.6528 | H14: =IFERROR(VLOOKUP($A13&H$2&$B14,Dados7030!$E$1:$F$360,2,FALSE), VLOOKUP($A13&H$2&$B14,Dados10Fold!$E$1:$F$360,2,FALSE)) -> 0.6941 | I14: =IFERROR(VLOOKUP($A13&I$2&$B14,Dados7030!$E$1:$F$360,2,FALSE), VLOOKUP($A13&I$2&$B14,Dados10Fold!$E$1:$F$360,2,FALSE)) -> 0.6455 | J14: =IFERROR(VLOOKUP($A13&J$2&$B14,Dados7030!$E$1:$F$360,2,FALSE), VLOOKUP($A13&J$2&$B14,Dados10Fold!$E$1:$F$360,2,FALSE)) -> 0.6813 | ... L14: =IFERROR(VLOOKUP($A13&L$2&$B14,Dados7030!$E$1:$F$360,2,FALSE), VLOOKUP($A13&L$2&$B14,Dados10Fold!$E$1:$F$360,2,FALSE)) -> 0.6696
A15: HOG_128_8x8.csv | B15: 70/30 | C15: =IFERROR(VLOOKUP($A15&C$2&$B15,Dados7030!$E$1:$F$360,2,FALSE), VLOOKUP($A15&C$2&$B15,Dados10Fold!$E$1:$F$360,2,FALSE)) -> 0.5236 | D15: =IFERROR(VLOOKUP($A15&D$2&$B15,Dados7030!$E$1:$F$360,2,FALSE), VLOOKUP($A15&D$2&$B15,Dados10Fold!$E$1:$F$360,2,FALSE)) -> 0.5574 | E15: =IFERROR(VLOOKUP($A15&E$2&$B15,Dados7030!$E$1:$F$360,2,FALSE), VLOOKUP($A15&E$2&$B15,Dados10Fold!$E$1:$F$360,2,FALSE)) -> 0.4975 | F15: =IFERROR(VLOOKUP($A15&F$2&$B15,Dados7030!$E$1:$F$360,2,FALSE), VLOOKUP($A15&F$2&$B15,Dados10Fold!$E$1:$F$360,2,FALSE)) -> 0.5514 | G15: =IFERROR(VLOOKUP($A15&G$2&$B15,Dados7030!$E$1:$F$360,2,FALSE), VLOOKUP($A15&G$2&$B15,Dados10Fold!$E$1:$F$360,2,FALSE)) -> 0.458 | H15: =IFERROR(VLOOKUP($A15&H$2&$B15,Dados7030!$E$1:$F$360,2,FALSE), VLOOKUP($A15&H$2&$B15,Dados10Fold!$E$1:$F$360,2,FALSE)) -> 0.5115 | I15: =IFERROR(VLOOKUP($A15&I$2&$B15,Dados7030!$E$1:$F$360,2,FALSE), VLOOKUP($A15&I$2&$B15,Dados10Fold!$E$1:$F$360,2,FALSE)) -> 0.4445 | J15: =IFERROR(VLOOKUP($A15&J$2&$B15,Dados7030!$E$1:$F$360,2,FALSE), VLOOKUP($A15&J$2&$B15,Dados10Fold!$E$1:$F$360,2,FALSE)) -> 0.4805 | ... L15: =IFERROR(VLOOKUP($A15&L$2&$B15,Dados7030!$E$1:$F$360,2,FALSE), VLOOKUP($A15&L$2&$B15,Dados10Fold!$E$1:$F$360,2,FALSE)) -> 0.4683 | M15: =MEDIAN(C15:L16) -> 0.4991 | O15: LBP_128_12r.csv
B16: 10Fold | C16: =IFERROR(VLOOKUP($A15&C$2&$B16,Dados7030!$E$1:$F$360,2,FALSE), VLOOKUP($A15&C$2&$B16,Dados10Fold!$E$1:$F$360,2,FALSE)) -> 0.5385 | D16: =IFERROR(VLOOKUP($A15&D$2&$B16,Dados7030!$E$1:$F$360,2,FALSE), VLOOKUP($A15&D$2&$B16,Dados10Fold!$E$1:$F$360,2,FALSE)) -> 0.5716 | E16: =IFERROR(VLOOKUP($A15&E$2&$B16,Dados7030!$E$1:$F$360,2,FALSE), VLOOKUP($A15&E$2&$B16,Dados10Fold!$E$1:$F$360,2,FALSE)) -> 0.5007 | F16: =IFERROR(VLOOKUP($A15&F$2&$B16,Dados7030!$E$1:$F$360,2,FALSE), VLOOKUP($A15&F$2&$B16,Dados10Fold!$E$1:$F$360,2,FALSE)) -> 0.5608 | G16: =IFERROR(VLOOKUP($A15&G$2&$B16,Dados7030!$E$1:$F$360,2,FALSE), VLOOKUP($A15&G$2&$B16,Dados10Fold!$E$1:$F$360,2,FALSE)) -> 0.4809 | H16: =IFERROR(VLOOKUP($A15&H$2&$B16,Dados7030!$E$1:$F$360,2,FALSE), VLOOKUP($A15&H$2&$B16,Dados10Fold!$E$1:$F$360,2,FALSE)) -> 0.5336 | I16: =IFERROR(VLOOKUP($A15&I$2&$B16,Dados7030!$E$1:$F$360,2,FALSE), VLOOKUP($A15&I$2&$B16,Dados10Fold!$E$1:$F$360,2,FALSE)) -> 0.469 | J16: =IFERROR(VLOOKUP($A15&J$2&$B16,Dados7030!$E$1:$F$360,2,FALSE), VLOOKUP($A15&J$2&$B16,Dados10Fold!$E$1:$F$360,2,FALSE)) -> 0.507 | ... L16: =IFERROR(VLOOKUP($A15&L$2&$B16,Dados7030!$E$1:$F$360,2,FALSE), VLOOKUP($A15&L$2&$B16,Dados10Fold!$E$1:$F$360,2,FALSE)) -> 0.4895
A17: HOG_128_8x8_PCA75.csv | B17: 70/30 | C17: =IFERROR(VLOOKUP($A17&C$2&$B17,Dados7030!$E$1:$F$360,2,FALSE), VLOOKUP($A17&C$2&$B17,Dados10Fold!$E$1:$F$360,2,FALSE)) -> 0.5281 | D17: =IFERROR(VLOOKUP($A17&D$2&$B17,Dados7030!$E$1:$F$360,2,FALSE), VLOOKUP($A17&D$2&$B17,Dados10Fold!$E$1:$F$360,2,FALSE)) -> 0.5668 | E17: =IFERROR(VLOOKUP($A17&E$2&$B17,Dados7030!$E$1:$F$360,2,FALSE), VLOOKUP($A17&E$2&$B17,Dados10Fold!$E$1:$F$360,2,FALSE)) -> 0.4944 | F17: =IFERROR(VLOOKUP($A17&F$2&$B17,Dados7030!$E$1:$F$360,2,FALSE), VLOOKUP($A17&F$2&$B17,Dados10Fold!$E$1:$F$360,2,FALSE)) -> 0.5264 | G17: =IFERROR(VLOOKUP($A17&G$2&$B17,Dados7030!$E$1:$F$360,2,FALSE), VLOOKUP($A17&G$2&$B17,Dados10Fold!$E$1:$F$360,2,FALSE)) -> 0.4646 | H17: =IFERROR(VLOOKUP($A17&H$2&$B17,Dados7030!$E$1:$F$360,2,FALSE), VLOOKUP($A17&H$2&$B17,Dados10Fold!$E$1:$F$360,2,FALSE)) -> 0.5157 | I17: =IFERROR(VLOOKUP($A17&I$2&$B17,Dados7030!$E$1:$F$360,2,FALSE), VLOOKUP($A17&I$2&$B17,Dados10Fold!$E$1:$F$360,2,FALSE)) -> 0.458 | J17: =IFERROR(VLOOKUP($A17&J$2&$B17,Dados7030!$E$1:$F$360,2,FALSE), VLOOKUP($A17&J$2&$B17,Dados10Fold!$E$1:$F$360,2,FALSE)) -> 0.4796 | ... L17: =IFERROR(VLOOKUP($A17&L$2&$B17,Dados7030!$E$1:$F$360,2,FALSE), VLOOKUP($A17&L$2&$B17,Dados10Fold!$E$1:$F$360,2,FALSE)) -> 0.4636 | M17: =MEDIAN(C17:L18) -> 0.50475 | O17: LBP_128_3r.csv
B18: 10Fold | C18: =IFERROR(VLOOKUP($A17&C$2&$B18,Dados7030!$E$1:$F$360,2,FALSE), VLOOKUP($A17&C$2&$B18,Dados10Fold!$E$1:$F$360,2,FALSE)) -> 0.5493 | D18: =IFERROR(VLOOKUP($A17&D$2&$B18,Dados7030!$E$1:$F$360,2,FALSE), VLOOKUP($A17&D$2&$B18,Dados10Fold!$E$1:$F$360,2,FALSE)) -> 0.5764 | E18: =IFERROR(VLOOKUP($A17&E$2&$B18,Dados7030!$E$1:$F$360,2,FALSE), VLOOKUP($A17&E$2&$B18,Dados10Fold!$E$1:$F$360,2,FALSE)) -> 0.5262 | F18: =IFERROR(VLOOKUP($A17&F$2&$B18,Dados7030!$E$1:$F$360,2,FALSE), VLOOKUP($A17&F$2&$B18,Dados10Fold!$E$1:$F$360,2,FALSE)) -> 0.5736 | G18: =IFERROR(VLOOKUP($A17&G$2&$B18,Dados7030!$E$1:$F$360,2,FALSE), VLOOKUP($A17&G$2&$B18,Dados10Fold!$E$1:$F$360,2,FALSE)) -> 0.4971 | H18: =IFERROR(VLOOKUP($A17&H$2&$B18,Dados7030!$E$1:$F$360,2,FALSE), VLOOKUP($A17&H$2&$B18,Dados10Fold!$E$1:$F$360,2,FALSE)) -> 0.5429 | I18: =IFERROR(VLOOKUP($A17&I$2&$B18,Dados7030!$E$1:$F$360,2,FALSE), VLOOKUP($A17&I$2&$B18,Dados10Fold!$E$1:$F$360,2,FALSE)) -> 0.4746 | J18: =IFERROR(VLOOKUP($A17&J$2&$B18,Dados7030!$E$1:$F$360,2,FALSE), VLOOKUP($A17&J$2&$B18,Dados10Fold!$E$1:$F$360,2,FALSE)) -> 0.5124 | ... L18: =IFERROR(VLOOKUP($A17&L$2&$B18,Dados7030!$E$1:$F$360,2,FALSE), VLOOKUP($A17&L$2&$B18,Dados10Fold!$E$1:$F$360,2,FALSE)) -> 0.4884
A19: HOG_128_8x8_PCA90.csv | B19: 70/30 | C19: =IFERROR(VLOOKUP($A19&C$2&$B19,Dados7030!$E$1:$F$360,2,FALSE), VLOOKUP($A19&C$2&$B19,Dados10Fold!$E$1:$F$360,2,FALSE)) -> 0.516 | D19: =IFERROR(VLOOKUP($A19&D$2&$B19,Dados7030!$E$1:$F$360,2,FALSE), VLOOKUP($A19&D$2&$B19,Dados10Fold!$E$1:$F$360,2,FALSE)) -> 0.5518 | E19: =IFERROR(VLOOKUP($A19&E$2&$B19,Dados7030!$E$1:$F$360,2,FALSE), VLOOKUP($A19&E$2&$B19,Dados10Fold!$E$1:$F$360,2,FALSE)) -> 0.4935 | F19: =IFERROR(VLOOKUP($A19&F$2&$B19,Dados7030!$E$1:$F$360,2,FALSE), VLOOKUP($A19&F$2&$B19,Dados10Fold!$E$1:$F$360,2,FALSE)) -> 0.5313 | G19: =IFERROR(VLOOKUP($A19&G$2&$B19,Dados7030!$E$1:$F$360,2,FALSE), VLOOKUP($A19&G$2&$B19,Dados10Fold!$E$1:$F$360,2,FALSE)) -> 0.4573 | H19: =IFERROR(VLOOKUP($A19&H$2&$B19,Dados7030!$E$1:$F$360,2,FALSE), VLOOKUP($A19&H$2&$B19,Dados10Fold!$E$1:$F$360,2,FALSE)) -> 0.4888 | I19: =IFERROR(VLOOKUP($A19&I$2&$B19,Dados7030!$E$1:$F$360,2,FALSE), VLOOKUP($A19&I$2&$B19,Dados10Fold!$E$1:$F$360,2,FALSE)) -> 0.4383 | J19: =IFERROR(VLOOKUP($A19&J$2&$B19,Dados7030!$E$1:$F$360,2,FALSE), VLOOKUP($A19&J$2&$B19,Dados10Fold!$E$1:$F$360,2,FALSE)) -> 0.4734 | ... L19: =IFERROR(VLOOKUP($A19&L$2&$B19,Dados7030!$E$1:$F$360,2,FALSE), VLOOKUP($A19&L$2&$B19,Dados10Fold!$E$1:$F$360,2,FALSE)) -> 0.4588 | M19: =MEDIAN(C19:L20) -> 0.49035 | O19: LBP_128_3r_PCA90.csv
B20: 10Fold | C20: =IFERROR(VLOOKUP($A19&C$2&$B20,Dados7030!$E$1:$F$360,2,FALSE), VLOOKUP($A19&C$2&$B20,Dados10Fold!$E$1:$F$360,2,FALSE)) -> 0.5361 | D20: =IFERROR(VLOOKUP($A19&D$2&$B20,Dados7030!$E$1:$F$360,2,FALSE), VLOOKUP($A19&D$2&$B20,Dados10Fold!$E$1:$F$360,2,FALSE)) -> 0.5668 | E20: =IFERROR(VLOOKUP($A19&E$2&$B20,Dados7030!$E$1:$F$360,2,FALSE), VLOOKUP($A19&E$2&$B20,Dados10Fold!$E$1:$F$360,2,FALSE)) -> 0.5043 | F20: =IFERROR(VLOOKUP($A19&F$2&$B20,Dados7030!$E$1:$F$360,2,FALSE), VLOOKUP($A19&F$2&$B20,Dados10Fold!$E$1:$F$360,2,FALSE)) -> 0.5521 | G20: =IFERROR(VLOOKUP($A19&G$2&$B20,Dados7030!$E$1:$F$360,2,FALSE), VLOOKUP($A19&G$2&$B20,Dados10Fold!$E$1:$F$360,2,FALSE)) -> 0.4761 | H20: =IFERROR(VLOOKUP($A19&H$2&$B20,Dados7030!$E$1:$F$360,2,FALSE), VLOOKUP($A19&H$2&$B20,Dados10Fold!$E$1:$F$360,2,FALSE)) -> 0.5252 | I20: =IFERROR(VLOOKUP($A19&I$2&$B20,Dados7030!$E$1:$F$360,2,FALSE), VLOOKUP($A19&I$2&$B20,Dados10Fold!$E$1:$F$360,2,FALSE)) -> 0.4536 | J20: =IFERROR(VLOOKUP($A19&J$2&$B20,Dados7030!$E$1:$F$360,2,FALSE), VLOOKUP($A19&J$2&$B20,Dados10Fold!$E$1:$F$360,2,FALSE)) -> 0.4919 | ... L20: =IFERROR(VLOOKUP($A19&L$2&$B20,Dados7030!$E$1:$F$360,2,FALSE), VLOOKUP($A19&L$2&$B20,Dados10Fold!$E$1:$F$360,2,FALSE)) -> 0.4764
A21: HOG_256_16x16.csv | B21: 70/30 | C21: =IFERROR(VLOOKUP($A21&C$2&$B21,Dados7030!$E$1:$F$360,2,FALSE), VLOOKUP($A21&C$2&$B21,Dados10Fold!$E$1:$F$360,2,FALSE)) -> 0.4953 | D21: =IFERROR(VLOOKUP($A21&D$2&$B21,Dados7030!$E$1:$F$360,2,FALSE), VLOOKUP($A21&D$2&$B21,Dados10Fold!$E$1:$F$360,2,FALSE)) -> 0.5292 | E21: =IFERROR(VLOOKUP($A21&E$2&$B21,Dados7030!$E$1:$F$360,2,FALSE), VLOOKUP($A21&E$2&$B21,Dados10Fold!$E$1:$F$360,2,FALSE)) -> 0.4787 | F21: =IFERROR(VLOOKUP($A21&F$2&$B21,Dados7030!$E$1:$F$360,2,FALSE), VLOOKUP($A21&F$2&$B21,Dados10Fold!$E$1:$F$360,2,FALSE)) -> 0.5093 | G21: =IFERROR(VLOOKUP($A21&G$2&$B21,Dados7030!$E$1:$F$360,2,FALSE), VLOOKUP($A21&G$2&$B21,Dados10Fold!$E$1:$F$360,2,FALSE)) -> 0.4534 | H21: =IFERROR(VLOOKUP($A21&H$2&$B21,Dados7030!$E$1:$F$360,2,FALSE), VLOOKUP($A21&H$2&$B21,Dados10Fold!$E$1:$F$360,2,FALSE)) -> 0.48 | I21: =IFERROR(VLOOKUP($A21&I$2&$B21,Dados7030!$E$1:$F$360,2,FALSE), VLOOKUP($A21&I$2&$B21,Dados10Fold!$E$1:$F$360,2,FALSE)) -> 0.4332 | J21: =IFERROR(VLOOKUP($A21&J$2&$B21,Dados7030!$E$1:$F$360,2,FALSE), VLOOKUP($A21&J$2&$B21,Dados10Fold!$E$1:$F$360,2,FALSE)) -> 0.474 | ... L21: =IFERROR(VLOOKUP($A21&L$2&$B21,Dados7030!$E$1:$F$360,2,FALSE), VLOOKUP($A21&L$2&$B21,Dados10Fold!$E$1:$F$360,2,FALSE)) -> 0.4634 | M21: =MEDIAN(C21:L22) -> 0.4802 | O21: LBP_128_6r.csv
B22: 10Fold | C22: =IFERROR(VLOOKUP($A21&C$2&$B22,Dados7030!$E$1:$F$360,2,FALSE), VLOOKUP($A21&C$2&$B22,Dados10Fold!$E$1:$F$360,2,FALSE)) -> 0.5604 | D22: =IFERROR(VLOOKUP($A21&D$2&$B22,Dados7030!$E$1:$F$360,2,FALSE), VLOOKUP($A21&D$2&$B22,Dados10Fold!$E$1:$F$360,2,FALSE)) -> 0.588 | E22: =IFERROR(VLOOKUP($A21&E$2&$B22,Dados7030!$E$1:$F$360,2,FALSE), VLOOKUP($A21&E$2&$B22,Dados10Fold!$E$1:$F$360,2,FALSE)) -> 0.5075 | F22: =IFERROR(VLOOKUP($A21&F$2&$B22,Dados7030!$E$1:$F$360,2,FALSE), VLOOKUP($A21&F$2&$B22,Dados10Fold!$E$1:$F$360,2,FALSE)) -> 0.5572 | G22: =IFERROR(VLOOKUP($A21&G$2&$B22,Dados7030!$E$1:$F$360,2,FALSE), VLOOKUP($A21&G$2&$B22,Dados10Fold!$E$1:$F$360,2,FALSE)) -> 0.4804 | H22: =IFERROR(VLOOKUP($A21&H$2&$B22,Dados7030!$E$1:$F$360,2,FALSE), VLOOKUP($A21&H$2&$B22,Dados10Fold!$E$1:$F$360,2,FALSE)) -> 0.5248 | I22: =IFERROR(VLOOKUP($A21&I$2&$B22,Dados7030!$E$1:$F$360,2,FALSE), VLOOKUP($A21&I$2&$B22,Dados10Fold!$E$1:$F$360,2,FALSE)) -> 0.4427 | J22: =IFERROR(VLOOKUP($A21&J$2&$B22,Dados7030!$E$1:$F$360,2,FALSE), VLOOKUP($A21&J$2&$B22,Dados10Fold!$E$1:$F$360,2,FALSE)) -> 0.4852 | ... L22: =IFERROR(VLOOKUP($A21&L$2&$B22,Dados7030!$E$1:$F$360,2,FALSE), VLOOKUP($A21&L$2&$B22,Dados10Fold!$E$1:$F$360,2,FALSE)) -> 0.4608
A23: HOG_256_16x16_PCA75.csv | B23: 70/30 | C23: =IFERROR(VLOOKUP($A23&C$2&$B23,Dados7030!$E$1:$F$360,2,FALSE), VLOOKUP($A23&C$2&$B23,Dados10Fold!$E$1:$F$360,2,FALSE)) -> 0.5512 | D23: =IFERROR(VLOOKUP($A23&D$2&$B23,Dados7030!$E$1:$F$360,2,FALSE), VLOOKUP($A23&D$2&$B23,Dados10Fold!$E$1:$F$360,2,FALSE)) -> 0.5794 | E23: =IFERROR(VLOOKUP($A23&E$2&$B23,Dados7030!$E$1:$F$360,2,FALSE), VLOOKUP($A23&E$2&$B23,Dados10Fold!$E$1:$F$360,2,FALSE)) -> 0.5047 | F23: =IFERROR(VLOOKUP($A23&F$2&$B23,Dados7030!$E$1:$F$360,2,FALSE), VLOOKUP($A23&F$2&$B23,Dados10Fold!$E$1:$F$360,2,FALSE)) -> 0.5488 | G23: =IFERROR(VLOOKUP($A23&G$2&$B23,Dados7030!$E$1:$F$360,2,FALSE), VLOOKUP($A23&G$2&$B23,Dados10Fold!$E$1:$F$360,2,FALSE)) -> 0.4962 | H23: =IFERROR(VLOOKUP($A23&H$2&$B23,Dados7030!$E$1:$F$360,2,FALSE), VLOOKUP($A23&H$2&$B23,Dados10Fold!$E$1:$F$360,2,FALSE)) -> 0.5265 | I23: =IFERROR(VLOOKUP($A23&I$2&$B23,Dados7030!$E$1:$F$360,2,FALSE), VLOOKUP($A23&I$2&$B23,Dados10Fold!$E$1:$F$360,2,FALSE)) -> 0.4812 | J23: =IFERROR(VLOOKUP($A23&J$2&$B23,Dados7030!$E$1:$F$360,2,FALSE), VLOOKUP($A23&J$2&$B23,Dados10Fold!$E$1:$F$360,2,FALSE)) -> 0.5038 | ... L23: =IFERROR(VLOOKUP($A23&L$2&$B23,Dados7030!$E$1:$F$360,2,FALSE), VLOOKUP($A23&L$2&$B23,Dados10Fold!$E$1:$F$360,2,FALSE)) -> 0.5002 | M23: =MEDIAN(C23:L24) -> 0.52215 | O23: LBP_128_6r_PCA75.csv
B24: 10Fold | C24: =IFERROR(VLOOKUP($A23&C$2&$B24,Dados7030!$E$1:$F$360,2,FALSE), VLOOKUP($A23&C$2&$B24,Dados10Fold!$E$1:$F$360,2,FALSE)) -> 0.5816 | D24: =IFERROR(VLOOKUP($A23&D$2&$B24,Dados7030!$E$1:$F$360,2,FALSE), VLOOKUP($A23&D$2&$B24,Dados10Fold!$E$1:$F$360,2,FALSE)) -> 0.6061 | E24: =IFERROR(VLOOKUP($A23&E$2&$B24,Dados7030!$E$1:$F$360,2,FALSE), VLOOKUP($A23&E$2&$B24,Dados10Fold!$E$1:$F$360,2,FALSE)) -> 0.5501 | F24: =IFERROR(VLOOKUP($A23&F$2&$B24,Dados7030!$E$1:$F$360,2,FALSE), VLOOKUP($A23&F$2&$B24,Dados10Fold!$E$1:$F$360,2,FALSE)) -> 0.5979 | G24: =IFERROR(VLOOKUP($A23&G$2&$B24,Dados7030!$E$1:$F$360,2,FALSE), VLOOKUP($A23&G$2&$B24,Dados10Fold!$E$1:$F$360,2,FALSE)) -> 0.5178 | H24: =IFERROR(VLOOKUP($A23&H$2&$B24,Dados7030!$E$1:$F$360,2,FALSE), VLOOKUP($A23&H$2&$B24,Dados10Fold!$E$1:$F$360,2,FALSE)) -> 0.5643 | I24: =IFERROR(VLOOKUP($A23&I$2&$B24,Dados7030!$E$1:$F$360,2,FALSE), VLOOKUP($A23&I$2&$B24,Dados10Fold!$E$1:$F$360,2,FALSE)) -> 0.4943 | J24: =IFERROR(VLOOKUP($A23&J$2&$B24,Dados7030!$E$1:$F$360,2,FALSE), VLOOKUP($A23&J$2&$B24,Dados10Fold!$E$1:$F$360,2,FALSE)) -> 0.538 | ... L24: =IFERROR(VLOOKUP($A23&L$2&$B24,Dados7030!$E$1:$F$360,2,FALSE), VLOOKUP($A23&L$2&$B24,Dados10Fold!$E$1:$F$360,2,FALSE)) -> 0.5127
A25: HOG_256_16x16_PCA90.csv | B25: 70/30 | C25: =IFERROR(VLOOKUP($A25&C$2&$B25,Dados7030!$E$1:$F$360,2,FALSE), VLOOKUP($A25&C$2&$B25,Dados10Fold!$E$1:$F$360,2,FALSE)) -> 0.5079 | D25: =IFERROR(VLOOKUP($A25&D$2&$B25,Dados7030!$E$1:$F$360,2,FALSE), VLOOKUP($A25&D$2&$B25,Dados10Fold!$E$1:$F$360,2,FALSE)) -> 0.5445 | E25: =IFERROR(VLOOKUP($A25&E$2&$B25,Dados7030!$E$1:$F$360,2,FALSE), VLOOKUP($A25&E$2&$B25,Dados10Fold!$E$1:$F$360,2,FALSE)) -> 0.4807 | F25: =IFERROR(VLOOKUP($A25&F$2&$B25,Dados7030!$E$1:$F$360,2,FALSE), VLOOKUP($A25&F$2&$B25,Dados10Fold!$E$1:$F$360,2,FALSE)) -> 0.5124 | G25: =IFERROR(VLOOKUP($A25&G$2&$B25,Dados7030!$E$1:$F$360,2,FALSE), VLOOKUP($A25&G$2&$B25,Dados10Fold!$E$1:$F$360,2,FALSE)) -> 0.4537 | H25: =IFERROR(VLOOKUP($A25&H$2&$B25,Dados7030!$E$1:$F$360,2,FALSE), VLOOKUP($A25&H$2&$B25,Dados10Fold!$E$1:$F$360,2,FALSE)) -> 0.4831 | I25: =IFERROR(VLOOKUP($A25&I$2&$B25,Dados7030!$E$1:$F$360,2,FALSE), VLOOKUP($A25&I$2&$B25,Dados10Fold!$E$1:$F$360,2,FALSE)) -> 0.4392 | J25: =IFERROR(VLOOKUP($A25&J$2&$B25,Dados7030!$E$1:$F$360,2,FALSE), VLOOKUP($A25&J$2&$B25,Dados10Fold!$E$1:$F$360,2,FALSE)) -> 0.4741 | ... L25: =IFERROR(VLOOKUP($A25&L$2&$B25,Dados7030!$E$1:$F$360,2,FALSE), VLOOKUP($A25&L$2&$B25,Dados10Fold!$E$1:$F$360,2,FALSE)) -> 0.4512 | M25: =MEDIAN(C25:L26) -> 0.4819 | O25: LBP_128_6r_PCA90.csv
B26: 10Fold | C26: =IFERROR(VLOOKUP($A25&C$2&$B26,Dados7030!$E$1:$F$360,2,FALSE), VLOOKUP($A25&C$2&$B26,Dados10Fold!$E$1:$F$360,2,FALSE)) -> 0.5628 | D26: =IFERROR(VLOOKUP($A25&D$2&$B26,Dados7030!$E$1:$F$360,2,FALSE), VLOOKUP($A25&D$2&$B26,Dados10Fold!$E$1:$F$360,2,FALSE)) -> 0.5907 | E26: =IFERROR(VLOOKUP($A25&E$2&$B26,Dados7030!$E$1:$F$360,2,FALSE), VLOOKUP($A25&E$2&$B26,Dados10Fold!$E$1:$F$360,2,FALSE)) -> 0.5205 | F26: =IFERROR(VLOOKUP($A25&F$2&$B26,Dados7030!$E$1:$F$360,2,FALSE), VLOOKUP($A25&F$2&$B26,Dados10Fold!$E$1:$F$360,2,FALSE)) -> 0.5641 | G26: =IFERROR(VLOOKUP($A25&G$2&$B26,Dados7030!$E$1:$F$360,2,FALSE), VLOOKUP($A25&G$2&$B26,Dados10Fold!$E$1:$F$360,2,FALSE)) -> 0.4765 | H26: =IFERROR(VLOOKUP($A25&H$2&$B26,Dados7030!$E$1:$F$360,2,FALSE), VLOOKUP($A25&H$2&$B26,Dados10Fold!$E$1:$F$360,2,FALSE)) -> 0.5275 | I26: =IFERROR(VLOOKUP($A25&I$2&$B26,Dados7030!$E$1:$F$360,2,FALSE), VLOOKUP($A25&I$2&$B26,Dados10Fold!$E$1:$F$360,2,FALSE)) -> 0.4489 | J26: =IFERROR(VLOOKUP($A25&J$2&$B26,Dados7030!$E$1:$F$360,2,FALSE), VLOOKUP($A25&J$2&$B26,Dados10Fold!$E$1:$F$360,2,FALSE)) -> 0.4888 | ... L26: =IFERROR(VLOOKUP($A25&L$2&$B26,Dados7030!$E$1:$F$360,2,FALSE), VLOOKUP($A25&L$2&$B26,Dados10Fold!$E$1:$F$360,2,FALSE)) -> 0.464
A27: HOG_256_32x32.csv | B27: 70/30 | C27: =IFERROR(VLOOKUP($A27&C$2&$B27,Dados7030!$E$1:$F$360,2,FALSE), VLOOKUP($A27&C$2&$B27,Dados10Fold!$E$1:$F$360,2,FALSE)) -> 0.5959 | D27: =IFERROR(VLOOKUP($A27&D$2&$B27,Dados7030!$E$1:$F$360,2,FALSE), VLOOKUP($A27&D$2&$B27,Dados10Fold!$E$1:$F$360,2,FALSE)) -> 0.6426 | E27: =IFERROR(VLOOKUP($A27&E$2&$B27,Dados7030!$E$1:$F$360,2,FALSE), VLOOKUP($A27&E$2&$B27,Dados10Fold!$E$1:$F$360,2,FALSE)) -> 0.5584 | F27: =IFERROR(VLOOKUP($A27&F$2&$B27,Dados7030!$E$1:$F$360,2,FALSE), VLOOKUP($A27&F$2&$B27,Dados10Fold!$E$1:$F$360,2,FALSE)) -> 0.5977 | G27: =IFERROR(VLOOKUP($A27&G$2&$B27,Dados7030!$E$1:$F$360,2,FALSE), VLOOKUP($A27&G$2&$B27,Dados10Fold!$E$1:$F$360,2,FALSE)) -> 0.5506 | H27: =IFERROR(VLOOKUP($A27&H$2&$B27,Dados7030!$E$1:$F$360,2,FALSE), VLOOKUP($A27&H$2&$B27,Dados10Fold!$E$1:$F$360,2,FALSE)) -> 0.578 | I27: =IFERROR(VLOOKUP($A27&I$2&$B27,Dados7030!$E$1:$F$360,2,FALSE), VLOOKUP($A27&I$2&$B27,Dados10Fold!$E$1:$F$360,2,FALSE)) -> 0.5271 | J27: =IFERROR(VLOOKUP($A27&J$2&$B27,Dados7030!$E$1:$F$360,2,FALSE), VLOOKUP($A27&J$2&$B27,Dados10Fold!$E$1:$F$360,2,FALSE)) -> 0.5605 | ... L27: =IFERROR(VLOOKUP($A27&L$2&$B27,Dados7030!$E$1:$F$360,2,FALSE), VLOOKUP($A27&L$2&$B27,Dados10Fold!$E$1:$F$360,2,FALSE)) -> 0.549 | M27: =MEDIAN(C27:L28) -> 0.57215 | O27: LBP_256_12r.csv
B28: 10Fold | C28: =IFERROR(VLOOKUP($A27&C$2&$B28,Dados7030!$E$1:$F$360,2,FALSE), VLOOKUP($A27&C$2&$B28,Dados10Fold!$E$1:$F$360,2,FALSE)) -> 0.6205 | D28: =IFERROR(VLOOKUP($A27&D$2&$B28,Dados7030!$E$1:$F$360,2,FALSE), VLOOKUP($A27&D$2&$B28,Dados10Fold!$E$1:$F$360,2,FALSE)) -> 0.6542 | E28: =IFERROR(VLOOKUP($A27&E$2&$B28,Dados7030!$E$1:$F$360,2,FALSE), VLOOKUP($A27&E$2&$B28,Dados10Fold!$E$1:$F$360,2,FALSE)) -> 0.5918 | F28: =IFERROR(VLOOKUP($A27&F$2&$B28,Dados7030!$E$1:$F$360,2,FALSE), VLOOKUP($A27&F$2&$B28,Dados10Fold!$E$1:$F$360,2,FALSE)) -> 0.6289 | G28: =IFERROR(VLOOKUP($A27&G$2&$B28,Dados7030!$E$1:$F$360,2,FALSE), VLOOKUP($A27&G$2&$B28,Dados10Fold!$E$1:$F$360,2,FALSE)) -> 0.5638 | H28: =IFERROR(VLOOKUP($A27&H$2&$B28,Dados7030!$E$1:$F$360,2,FALSE), VLOOKUP($A27&H$2&$B28,Dados10Fold!$E$1:$F$360,2,FALSE)) -> 0.6032 | I28: =IFERROR(VLOOKUP($A27&I$2&$B28,Dados7030!$E$1:$F$360,2,FALSE), VLOOKUP($A27&I$2&$B28,Dados10Fold!$E$1:$F$360,2,FALSE)) -> 0.547 | J28: =IFERROR(VLOOKUP($A27&J$2&$B28,Dados7030!$E$1:$F$360,2,FALSE), VLOOKUP($A27&J$2&$B28,Dados10Fold!$E$1:$F$360,2,FALSE)) -> 0.5807 | ... L28: =IFERROR(VLOOKUP($A27&L$2&$B28,Dados7030!$E$1:$F$360,2,FALSE), VLOOKUP($A27&L$2&$B28,Dados10Fold!$E$1:$F$360,2,FALSE)) -> 0.5663
A29: HOG_256_32x32_PCA75.csv | B29: 70/30 | C29: =IFERROR(VLOOKUP($A29&C$2&$B29,Dados7030!$E$1:$F$360,2,FALSE), VLOOKUP($A29&C$2&$B29,Dados10Fold!$E$1:$F$360,2,FALSE)) -> 0.6542 | D29: =IFERROR(VLOOKUP($A29&D$2&$B29,Dados7030!$E$1:$F$360,2,FALSE), VLOOKUP($A29&D$2&$B29,Dados10Fold!$E$1:$F$360,2,FALSE)) -> 0.6739 | E29: =IFERROR(VLOOKUP($A29&E$2&$B29,Dados7030!$E$1:$F$360,2,FALSE), VLOOKUP($A29&E$2&$B29,Dados10Fold!$E$1:$F$360,2,FALSE)) -> 0.6463 | F29: =IFERROR(VLOOKUP($A29&F$2&$B29,Dados7030!$E$1:$F$360,2,FALSE), VLOOKUP($A29&F$2&$B29,Dados10Fold!$E$1:$F$360,2,FALSE)) -> 0.6669 | G29: =IFERROR(VLOOKUP($A29&G$2&$B29,Dados7030!$E$1:$F$360,2,FALSE), VLOOKUP($A29&G$2&$B29,Dados10Fold!$E$1:$F$360,2,FALSE)) -> 0.6344 | H29: =IFERROR(VLOOKUP($A29&H$2&$B29,Dados7030!$E$1:$F$360,2,FALSE), VLOOKUP($A29&H$2&$B29,Dados10Fold!$E$1:$F$360,2,FALSE)) -> 0.6653 | I29: =IFERROR(VLOOKUP($A29&I$2&$B29,Dados7030!$E$1:$F$360,2,FALSE), VLOOKUP($A29&I$2&$B29,Dados10Fold!$E$1:$F$360,2,FALSE)) -> 0.6292 | J29: =IFERROR(VLOOKUP($A29&J$2&$B29,Dados7030!$E$1:$F$360,2,FALSE), VLOOKUP($A29&J$2&$B29,Dados10Fold!$E$1:$F$360,2,FALSE)) -> 0.6612 | ... L29: =IFERROR(VLOOKUP($A29&L$2&$B29,Dados7030!$E$1:$F$360,2,FALSE), VLOOKUP($A29&L$2&$B29,Dados10Fold!$E$1:$F$360,2,FALSE)) -> 0.6612 | M29: =MEDIAN(C29:L30) -> 0.661 | O29: LBP_256_12r_PCA90.csv
B30: 10Fold | C30: =IFERROR(VLOOKUP($A29&C$2&$B30,Dados7030!$E$1:$F$360,2,FALSE), VLOOKUP($A29&C$2&$B30,Dados10Fold!$E$1:$F$360,2,FALSE)) -> 0.6665 | D30: =IFERROR(VLOOKUP($A29&D$2&$B30,Dados7030!$E$1:$F$360,2,FALSE), VLOOKUP($A29&D$2&$B30,Dados10Fold!$E$1:$F$360,2,FALSE)) -> 0.6844 | E30: =IFERROR(VLOOKUP($A29&E$2&$B30,Dados7030!$E$1:$F$360,2,FALSE), VLOOKUP($A29&E$2&$B30,Dados10Fold!$E$1:$F$360,2,FALSE)) -> 0.6575 | F30: =IFERROR(VLOOKUP($A29&F$2&$B30,Dados7030!$E$1:$F$360,2,FALSE), VLOOKUP($A29&F$2&$B30,Dados10Fold!$E$1:$F$360,2,FALSE)) -> 0.6822 | G30: =IFERROR(VLOOKUP($A29&G$2&$B30,Dados7030!$E$1:$F$360,2,FALSE), VLOOKUP($A29&G$2&$B30,Dados10Fold!$E$1:$F$360,2,FALSE)) -> 0.6456 | H30: =IFERROR(VLOOKUP($A29&H$2&$B30,Dados7030!$E$1:$F$360,2,FALSE), VLOOKUP($A29&H$2&$B30,Dados10Fold!$E$1:$F$360,2,FALSE)) -> 0.6801 | I30: =IFERROR(VLOOKUP($A29&I$2&$B30,Dados7030!$E$1:$F$360,2,FALSE), VLOOKUP($A29&I$2&$B30,Dados10Fold!$E$1:$F$360,2,FALSE)) -> 0.6386 | J30: =IFERROR(VLOOKUP($A29&J$2&$B30,Dados7030!$E$1:$F$360,2,FALSE), VLOOKUP($A29&J$2&$B30,Dados10Fold!$E$1:$F$360,2,FALSE)) -> 0.6678 | ... L30: =IFERROR(VLOOKUP($A29&L$2&$B30,Dados7030!$E$1:$F$360,2,FALSE), VLOOKUP($A29&L$2&$B30,Dados10Fold!$E$1:$F$360,2,FALSE)) -> 0.6608
A31: HOG_256_32x32_PCA90.csv | B31: 70/30 | C31: =IFERROR(VLOOKUP($A31&C$2&$B31,Dados7030!$E$1:$F$360,2,FALSE), VLOOKUP($A31&C$2&$B31,Dados10Fold!$E$1:$F$360,2,FALSE)) -> 0.6184 | D31: =IFERROR(VLOOKUP($A31&D$2&$B31,Dados7030!$E$1:$F$360,2,FALSE), VLOOKUP($A31&D$2&$B31,Dados10Fold!$E$1:$F$360,2,FALSE)) -> 0.6472 | E31: =IFERROR(VLOOKUP($A31&E$2&$B31,Dados7030!$E$1:$F$360,2,FALSE), VLOOKUP($A31&E$2&$B31,Dados10Fold!$E$1:$F$360,2,FALSE)) -> 0.587 | F31: =IFERROR(VLOOKUP($A31&F$2&$B31,Dados7030!$E$1:$F$360,2,FALSE), VLOOKUP($A31&F$2&$B31,Dados10Fold!$E$1:$F$360,2,FALSE)) -> 0.6324 | G31: =IFERROR(VLOOKUP($A31&G$2&$B31,Dados7030!$E$1:$F$360,2,FALSE), VLOOKUP($A31&G$2&$B31,Dados10Fold!$E$1:$F$360,2,FALSE)) -> 0.5686 | H31: =IFERROR(VLOOKUP($A31&H$2&$B31,Dados7030!$E$1:$F$360,2,FALSE), VLOOKUP($A31&H$2&$B31,Dados10Fold!$E$1:$F$360,2,FALSE)) -> 0.6025 | I31: =IFERROR(VLOOKUP($A31&I$2&$B31,Dados7030!$E$1:$F$360,2,FALSE), VLOOKUP($A31&I$2&$B31,Dados10Fold!$E$1:$F$360,2,FALSE)) -> 0.5607 | J31: =IFERROR(VLOOKUP($A31&J$2&$B31,Dados7030!$E$1:$F$360,2,FALSE), VLOOKUP($A31&J$2&$B31,Dados10Fold!$E$1:$F$360,2,FALSE)) -> 0.5917 | ... L31: =IFERROR(VLOOKUP($A31&L$2&$B31,Dados7030!$E$1:$F$360,2,FALSE), VLOOKUP($A31&L$2&$B31,Dados10Fold!$E$1:$F$360,2,FALSE)) -> 0.5838 | M31: =MEDIAN(C31:L32) -> 0.5979 | O31: LBP_256_6r.csv
B32: 10Fold | C32: =IFERROR(VLOOKUP($A31&C$2&$B32,Dados7030!$E$1:$F$360,2,FALSE), VLOOKUP($A31&C$2&$B32,Dados10Fold!$E$1:$F$360,2,FALSE)) -> 0.641 | D32: =IFERROR(VLOOKUP($A31&D$2&$B32,Dados7030!$E$1:$F$360,2,FALSE), VLOOKUP($A31&D$2&$B32,Dados10Fold!$E$1:$F$360,2,FALSE)) -> 0.6757 | E32: =IFERROR(VLOOKUP($A31&E$2&$B32,Dados7030!$E$1:$F$360,2,FALSE), VLOOKUP($A31&E$2&$B32,Dados10Fold!$E$1:$F$360,2,FALSE)) -> 0.6139 | F32: =IFERROR(VLOOKUP($A31&F$2&$B32,Dados7030!$E$1:$F$360,2,FALSE), VLOOKUP($A31&F$2&$B32,Dados10Fold!$E$1:$F$360,2,FALSE)) -> 0.6541 | G32: =IFERROR(VLOOKUP($A31&G$2&$B32,Dados7030!$E$1:$F$360,2,FALSE), VLOOKUP($A31&G$2&$B32,Dados10Fold!$E$1:$F$360,2,FALSE)) -> 0.5933 | H32: =IFERROR(VLOOKUP($A31&H$2&$B32,Dados7030!$E$1:$F$360,2,FALSE), VLOOKUP($A31&H$2&$B32,Dados10Fold!$E$1:$F$360,2,FALSE)) -> 0.626 | I32: =IFERROR(VLOOKUP($A31&I$2&$B32,Dados7030!$E$1:$F$360,2,FALSE), VLOOKUP($A31&I$2&$B32,Dados10Fold!$E$1:$F$360,2,FALSE)) -> 0.5755 | J32: =IFERROR(VLOOKUP($A31&J$2&$B32,Dados7030!$E$1:$F$360,2,FALSE), VLOOKUP($A31&J$2&$B32,Dados10Fold!$E$1:$F$360,2,FALSE)) -> 0.605 | ... L32: =IFERROR(VLOOKUP($A31&L$2&$B32,Dados7030!$E$1:$F$360,2,FALSE), VLOOKUP($A31&L$2&$B32,Dados10Fold!$E$1:$F$360,2,FALSE)) -> 0.5926
A33: HOG_256_8x8.csv | B33: 70/30 | C33: =IFERROR(VLOOKUP($A33&C$2&$B33,Dados7030!$E$1:$F$360,2,FALSE), VLOOKUP($A33&C$2&$B33,Dados10Fold!$E$1:$F$360,2,FALSE)) -> 0.456 | D33: =IFERROR(VLOOKUP($A33&D$2&$B33,Dados7030!$E$1:$F$360,2,FALSE), VLOOKUP($A33&D$2&$B33,Dados10Fold!$E$1:$F$360,2,FALSE)) -> 0.5062 | E33: =IFERROR(VLOOKUP($A33&E$2&$B33,Dados7030!$E$1:$F$360,2,FALSE), VLOOKUP($A33&E$2&$B33,Dados10Fold!$E$1:$F$360,2,FALSE)) -> 0.453 | F33: =IFERROR(VLOOKUP($A33&F$2&$B33,Dados7030!$E$1:$F$360,2,FALSE), VLOOKUP($A33&F$2&$B33,Dados10Fold!$E$1:$F$360,2,FALSE)) -> 0.4795 | G33: =IFERROR(VLOOKUP($A33&G$2&$B33,Dados7030!$E$1:$F$360,2,FALSE), VLOOKUP($A33&G$2&$B33,Dados10Fold!$E$1:$F$360,2,FALSE)) -> 0.4392 | H33: =IFERROR(VLOOKUP($A33&H$2&$B33,Dados7030!$E$1:$F$360,2,FALSE), VLOOKUP($A33&H$2&$B33,Dados10Fold!$E$1:$F$360,2,FALSE)) -> 0.4733 | I33: =IFERROR(VLOOKUP($A33&I$2&$B33,Dados7030!$E$1:$F$360,2,FALSE), VLOOKUP($A33&I$2&$B33,Dados10Fold!$E$1:$F$360,2,FALSE)) -> 0.4302 | J33: =IFERROR(VLOOKUP($A33&J$2&$B33,Dados7030!$E$1:$F$360,2,FALSE), VLOOKUP($A33&J$2&$B33,Dados10Fold!$E$1:$F$360,2,FALSE)) -> 0.463 | ... L33: =IFERROR(VLOOKUP($A33&L$2&$B33,Dados7030!$E$1:$F$360,2,FALSE), VLOOKUP($A33&L$2&$B33,Dados10Fold!$E$1:$F$360,2,FALSE)) -> 0.4468 | M33: =MEDIAN(C33:L34) -> 0.46815 | O33: LBP_256_6r_PCA90.csv
B34: 10Fold | C34: =IFERROR(VLOOKUP($A33&C$2&$B34,Dados7030!$E$1:$F$360,2,FALSE), VLOOKUP($A33&C$2&$B34,Dados10Fold!$E$1:$F$360,2,FALSE)) -> 0.5669 | D34: =IFERROR(VLOOKUP($A33&D$2&$B34,Dados7030!$E$1:$F$360,2,FALSE), VLOOKUP($A33&D$2&$B34,Dados10Fold!$E$1:$F$360,2,FALSE)) -> 0.5427 | E34: =IFERROR(VLOOKUP($A33&E$2&$B34,Dados7030!$E$1:$F$360,2,FALSE), VLOOKUP($A33&E$2&$B34,Dados10Fold!$E$1:$F$360,2,FALSE)) -> 0.5109 | F34: =IFERROR(VLOOKUP($A33&F$2&$B34,Dados7030!$E$1:$F$360,2,FALSE), VLOOKUP($A33&F$2&$B34,Dados10Fold!$E$1:$F$360,2,FALSE)) -> 0.5475 | G34: =IFERROR(VLOOKUP($A33&G$2&$B34,Dados7030!$E$1:$F$360,2,FALSE), VLOOKUP($A33&G$2&$B34,Dados10Fold!$E$1:$F$360,2,FALSE)) -> 0.4783 | H34: =IFERROR(VLOOKUP($A33&H$2&$B34,Dados7030!$E$1:$F$360,2,FALSE), VLOOKUP($A33&H$2&$B34,Dados10Fold!$E$1:$F$360,2,FALSE)) -> 0.513 | I34: =IFERROR(VLOOKUP($A33&I$2&$B34,Dados7030!$E$1:$F$360,2,FALSE), VLOOKUP($A33&I$2&$B34,Dados10Fold!$E$1:$F$360,2,FALSE)) -> 0.4479 | J34: =IFERROR(VLOOKUP($A33&J$2&$B34,Dados7030!$E$1:$F$360,2,FALSE), VLOOKUP($A33&J$2&$B34,Dados10Fold!$E$1:$F$360,2,FALSE)) -> 0.4837 | ... L34: =IFERROR(VLOOKUP($A33&L$2&$B34,Dados7030!$E$1:$F$360,2,FALSE), VLOOKUP($A33&L$2&$B34,Dados10Fold!$E$1:$F$360,2,FALSE)) -> 0.455
A35: HOG_256_8x8_PCA75.csv | B35: 70/30 | C35: =IFERROR(VLOOKUP($A35&C$2&$B35,Dados7030!$E$1:$F$360,2,FALSE), VLOOKUP($A35&C$2&$B35,Dados10Fold!$E$1:$F$360,2,FALSE)) -> 0.4708 | D35: =IFERROR(VLOOKUP($A35&D$2&$B35,Dados7030!$E$1:$F$360,2,FALSE), VLOOKUP($A35&D$2&$B35,Dados10Fold!$E$1:$F$360,2,FALSE)) -> 0.5233 | E35: =IFERROR(VLOOKUP($A35&E$2&$B35,Dados7030!$E$1:$F$360,2,FALSE), VLOOKUP($A35&E$2&$B35,Dados10Fold!$E$1:$F$360,2,FALSE)) -> 0.4576 | F35: =IFERROR(VLOOKUP($A35&F$2&$B35,Dados7030!$E$1:$F$360,2,FALSE), VLOOKUP($A35&F$2&$B35,Dados10Fold!$E$1:$F$360,2,FALSE)) -> 0.4933 | G35: =IFERROR(VLOOKUP($A35&G$2&$B35,Dados7030!$E$1:$F$360,2,FALSE), VLOOKUP($A35&G$2&$B35,Dados10Fold!$E$1:$F$360,2,FALSE)) -> 0.4425 | H35: =IFERROR(VLOOKUP($A35&H$2&$B35,Dados7030!$E$1:$F$360,2,FALSE), VLOOKUP($A35&H$2&$B35,Dados10Fold!$E$1:$F$360,2,FALSE)) -> 0.4735 | I35: =IFERROR(VLOOKUP($A35&I$2&$B35,Dados7030!$E$1:$F$360,2,FALSE), VLOOKUP($A35&I$2&$B35,Dados10Fold!$E$1:$F$360,2,FALSE)) -> 0.4375 | J35: =IFERROR(VLOOKUP($A35&J$2&$B35,Dados7030!$E$1:$F$360,2,FALSE), VLOOKUP($A35&J$2&$B35,Dados10Fold!$E$1:$F$360,2,FALSE)) -> 0.4657 | ... L35: =IFERROR(VLOOKUP($A35&L$2&$B35,Dados7030!$E$1:$F$360,2,FALSE), VLOOKUP($A35&L$2&$B35,Dados10Fold!$E$1:$F$360,2,FALSE)) -> 0.4456 | M35: =MEDIAN(C35:L36) -> 0.47215
B36: 10Fold | C36: =IFERROR(VLOOKUP($A35&C$2&$B36,Dados7030!$E$1:$F$360,2,FALSE), VLOOKUP($A35&C$2&$B36,Dados10Fold!$E$1:$F$360,2,FALSE)) -> 0.5567 | D36: =IFERROR(VLOOKUP($A35&D$2&$B36,Dados7030!$E$1:$F$360,2,FALSE), VLOOKUP($A35&D$2&$B36,Dados10Fold!$E$1:$F$360,2,FALSE)) -> 0.5505 | E36: =IFERROR(VLOOKUP($A35&E$2&$B36,Dados7030!$E$1:$F$360,2,FALSE), VLOOKUP($A35&E$2&$B36,Dados10Fold!$E$1:$F$360,2,FALSE)) -> 0.5164 | F36: =IFERROR(VLOOKUP($A35&F$2&$B36,Dados7030!$E$1:$F$360,2,FALSE), VLOOKUP($A35&F$2&$B36,Dados10Fold!$E$1:$F$360,2,FALSE)) -> 0.5559 | G36: =IFERROR(VLOOKUP($A35&G$2&$B36,Dados7030!$E$1:$F$360,2,FALSE), VLOOKUP($A35&G$2&$B36,Dados10Fold!$E$1:$F$360,2,FALSE)) -> 0.4735 | H36: =IFERROR(VLOOKUP($A35&H$2&$B36,Dados7030!$E$1:$F$360,2,FALSE), VLOOKUP($A35&H$2&$B36,Dados10Fold!$E$1:$F$360,2,FALSE)) -> 0.5122 | I36: =IFERROR(VLOOKUP($A35&I$2&$B36,Dados7030!$E$1:$F$360,2,FALSE), VLOOKUP($A35&I$2&$B36,Dados10Fold!$E$1:$F$360,2,FALSE)) -> 0.4476 | J36: =IFERROR(VLOOKUP($A35&J$2&$B36,Dados7030!$E$1:$F$360,2,FALSE), VLOOKUP($A35&J$2&$B36,Dados10Fold!$E$1:$F$360,2,FALSE)) -> 0.4808 | ... L36: =IFERROR(VLOOKUP($A35&L$2&$B36,Dados7030!$E$1:$F$360,2,FALSE), VLOOKUP($A35&L$2&$B36,Dados10Fold!$E$1:$F$360,2,FALSE)) -> 0.4546
A37: HOG_256_8x8_PCA90.csv | B37: 70/30 | C37: =IFERROR(VLOOKUP($A37&C$2&$B37,Dados7030!$E$1:$F$360,2,FALSE), VLOOKUP($A37&C$2&$B37,Dados10Fold!$E$1:$F$360,2,FALSE)) -> 0.4516 | D37: =IFERROR(VLOOKUP($A37&D$2&$B37,Dados7030!$E$1:$F$360,2,FALSE), VLOOKUP($A37&D$2&$B37,Dados10Fold!$E$1:$F$360,2,FALSE)) -> 0.5091 | E37: =IFERROR(VLOOKUP($A37&E$2&$B37,Dados7030!$E$1:$F$360,2,FALSE), VLOOKUP($A37&E$2&$B37,Dados10Fold!$E$1:$F$360,2,FALSE)) -> 0.4403 | F37: =IFERROR(VLOOKUP($A37&F$2&$B37,Dados7030!$E$1:$F$360,2,FALSE), VLOOKUP($A37&F$2&$B37,Dados10Fold!$E$1:$F$360,2,FALSE)) -> 0.4755 | G37: =IFERROR(VLOOKUP($A37&G$2&$B37,Dados7030!$E$1:$F$360,2,FALSE), VLOOKUP($A37&G$2&$B37,Dados10Fold!$E$1:$F$360,2,FALSE)) -> 0.4272 | H37: =IFERROR(VLOOKUP($A37&H$2&$B37,Dados7030!$E$1:$F$360,2,FALSE), VLOOKUP($A37&H$2&$B37,Dados10Fold!$E$1:$F$360,2,FALSE)) -> 0.4528 | I37: =IFERROR(VLOOKUP($A37&I$2&$B37,Dados7030!$E$1:$F$360,2,FALSE), VLOOKUP($A37&I$2&$B37,Dados10Fold!$E$1:$F$360,2,FALSE)) -> 0.4222 | J37: =IFERROR(VLOOKUP($A37&J$2&$B37,Dados7030!$E$1:$F$360,2,FALSE), VLOOKUP($A37&J$2&$B37,Dados10Fold!$E$1:$F$360,2,FALSE)) -> 0.4459 | ... L37: =IFERROR(VLOOKUP($A37&L$2&$B37,Dados7030!$E$1:$F$360,2,FALSE), VLOOKUP($A37&L$2&$B37,Dados10Fold!$E$1:$F$360,2,FALSE)) -> 0.4285 | M37: =MEDIAN(C37:L38) -> 0.4522
B38: 10Fold | C38: =IFERROR(VLOOKUP($A37&C$2&$B38,Dados7030!$E$1:$F$360,2,FALSE), VLOOKUP($A37&C$2&$B38,Dados10Fold!$E$1:$F$360,2,FALSE)) -> 0.5592 | D38: =IFERROR(VLOOKUP($A37&D$2&$B38,Dados7030!$E$1:$F$360,2,FALSE), VLOOKUP($A37&D$2&$B38,Dados10Fold!$E$1:$F$360,2,FALSE)) -> 0.5364 | E38: =IFERROR(VLOOKUP($A37&E$2&$B38,Dados7030!$E$1:$F$360,2,FALSE), VLOOKUP($A37&E$2&$B38,Dados10Fold!$E$1:$F$360,2,FALSE)) -> 0.5063 | F38: =IFERROR(VLOOKUP($A37&F$2&$B38,Dados7030!$E$1:$F$360,2,FALSE), VLOOKUP($A37&F$2&$B38,Dados10Fold!$E$1:$F$360,2,FALSE)) -> 0.546 | G38: =IFERROR(VLOOKUP($A37&G$2&$B38,Dados7030!$E$1:$F$360,2,FALSE), VLOOKUP($A37&G$2&$B38,Dados10Fold!$E$1:$F$360,2,FALSE)) -> 0.4694 | H38: =IFERROR(VLOOKUP($A37&H$2&$B38,Dados7030!$E$1:$F$360,2,FALSE), VLOOKUP($A37&H$2&$B38,Dados10Fold!$E$1:$F$360,2,FALSE)) -> 0.5037 | I38: =IFERROR(VLOOKUP($A37&I$2&$B38,Dados7030!$E$1:$F$360,2,FALSE), VLOOKUP($A37&I$2&$B38,Dados10Fold!$E$1:$F$360,2,FALSE)) -> 0.4355 | J38: =IFERROR(VLOOKUP($A37&J$2&$B38,Dados7030!$E$1:$F$360,2,FALSE), VLOOKUP($A37&J$2&$B38,Dados10Fold!$E$1:$F$360,2,FALSE)) -> 0.4668 | ... L38: =IFERROR(VLOOKUP($A37&L$2&$B38,Dados7030!$E$1:$F$360,2,FALSE), VLOOKUP($A37&L$2&$B38,Dados10Fold!$E$1:$F$360,2,FALSE)) -> 0.4445
A39: LBP_128_12r.csv | B39: 70/30 | C39: =IFERROR(VLOOKUP($A39&C$2&$B39,Dados7030!$E$1:$F$360,2,FALSE), VLOOKUP($A39&C$2&$B39,Dados10Fold!$E$1:$F$360,2,FALSE)) -> 0.5636 | D39: =IFERROR(VLOOKUP($A39&D$2&$B39,Dados7030!$E$1:$F$360,2,FALSE), VLOOKUP($A39&D$2&$B39,Dados10Fold!$E$1:$F$360,2,FALSE)) -> 0.5382 | E39: =IFERROR(VLOOKUP($A39&E$2&$B39,Dados7030!$E$1:$F$360,2,FALSE), VLOOKUP($A39&E$2&$B39,Dados10Fold!$E$1:$F$360,2,FALSE)) -> 0.6088 | F39: =IFERROR(VLOOKUP($A39&F$2&$B39,Dados7030!$E$1:$F$360,2,FALSE), VLOOKUP($A39&F$2&$B39,Dados10Fold!$E$1:$F$360,2,FALSE)) -> 0.5742 | G39: =IFERROR(VLOOKUP($A39&G$2&$B39,Dados7030!$E$1:$F$360,2,FALSE), VLOOKUP($A39&G$2&$B39,Dados10Fold!$E$1:$F$360,2,FALSE)) -> 0.6142 | H39: =IFERROR(VLOOKUP($A39&H$2&$B39,Dados7030!$E$1:$F$360,2,FALSE), VLOOKUP($A39&H$2&$B39,Dados10Fold!$E$1:$F$360,2,FALSE)) -> 0.5949 | I39: =IFERROR(VLOOKUP($A39&I$2&$B39,Dados7030!$E$1:$F$360,2,FALSE), VLOOKUP($A39&I$2&$B39,Dados10Fold!$E$1:$F$360,2,FALSE)) -> 0.6113 | J39: =IFERROR(VLOOKUP($A39&J$2&$B39,Dados7030!$E$1:$F$360,2,FALSE), VLOOKUP($A39&J$2&$B39,Dados10Fold!$E$1:$F$360,2,FALSE)) -> 0.594 | ... L39: =IFERROR(VLOOKUP($A39&L$2&$B39,Dados7030!$E$1:$F$360,2,FALSE), VLOOKUP($A39&L$2&$B39,Dados10Fold!$E$1:$F$360,2,FALSE)) -> 0.613 | M39: =MEDIAN(C39:L40) -> 0.6085
B40: 10Fold | C40: =IFERROR(VLOOKUP($A39&C$2&$B40,Dados7030!$E$1:$F$360,2,FALSE), VLOOKUP($A39&C$2&$B40,Dados10Fold!$E$1:$F$360,2,FALSE)) -> 0.572 | D40: =IFERROR(VLOOKUP($A39&D$2&$B40,Dados7030!$E$1:$F$360,2,FALSE), VLOOKUP($A39&D$2&$B40,Dados10Fold!$E$1:$F$360,2,FALSE)) -> 0.5499 | E40: =IFERROR(VLOOKUP($A39&E$2&$B40,Dados7030!$E$1:$F$360,2,FALSE), VLOOKUP($A39&E$2&$B40,Dados10Fold!$E$1:$F$360,2,FALSE)) -> 0.5964 | F40: =IFERROR(VLOOKUP($A39&F$2&$B40,Dados7030!$E$1:$F$360,2,FALSE), VLOOKUP($A39&F$2&$B40,Dados10Fold!$E$1:$F$360,2,FALSE)) -> 0.5843 | G40: =IFERROR(VLOOKUP($A39&G$2&$B40,Dados7030!$E$1:$F$360,2,FALSE), VLOOKUP($A39&G$2&$B40,Dados10Fold!$E$1:$F$360,2,FALSE)) -> 0.6123 | H40: =IFERROR(VLOOKUP($A39&H$2&$B40,Dados7030!$E$1:$F$360,2,FALSE), VLOOKUP($A39&H$2&$B40,Dados10Fold!$E$1:$F$360,2,FALSE)) -> 0.6114 | I40: =IFERROR(VLOOKUP($A39&I$2&$B40,Dados7030!$E$1:$F$360,2,FALSE), VLOOKUP($A39&I$2&$B40,Dados10Fold!$E$1:$F$360,2,FALSE)) -> 0.6128 | J40: =IFERROR(VLOOKUP($A39&J$2&$B40,Dados7030!$E$1:$F$360,2,FALSE), VLOOKUP($A39&J$2&$B40,Dados10Fold!$E$1:$F$360,2,FALSE)) -> 0.6086 | ... L40: =IFERROR(VLOOKUP($A39&L$2&$B40,Dados7030!$E$1:$F$360,2,FALSE), VLOOKUP($A39&L$2&$B40,Dados10Fold!$E$1:$F$360,2,FALSE)) -> 0.6248
...

Sheet Dados7030
A1: 70/30 | B1: HOG_128_16x16.csv | C1: Knn1 | D1: 5821 | E1: =B1&C1&A1 -> HOG_128_16x16.csvKnn170/30 | F1: =DIVIDE(D1,10000) -> 0.5821
A2: 70/30 | B2: HOG_128_16x16.csv | C2: Knn2 | D2: 6258 | E2: =B2&C2&A2 -> HOG_128_16x16.csvKnn270/30 | F2: =DIVIDE(D2,10000) -> 0.6258
A3: 70/30 | B3: HOG_128_16x16.csv | C3: Knn3 | D3: 5479 | E3: =B3&C3&A3 -> HOG_128_16x16.csvKnn370/30 | F3: =DIVIDE(D3,10000) -> 0.5479
A4: 70/30 | B4: HOG_128_16x16.csv | C4: Knn4 | D4: 5978 | E4: =B4&C4&A4 -> HOG_128_16x16.csvKnn470/30 | F4: =DIVIDE(D4,10000) -> 0.5978
A5: 70/30 | B5: HOG_128_16x16.csv | C5: Knn5 | D5: 5420 | E5: =B5&C5&A5 -> HOG_128_16x16.csvKnn570/30 | F5: =DIVIDE(D5,10000) -> 0.542
A6: 70/30 | B6: HOG_128_16x16.csv | C6: Knn6 | D6: 5740 | E6: =B6&C6&A6 -> HOG_128_16x16.csvKnn670/30 | F6: =DIVIDE(D6,10000) -> 0.574
A7: 70/30 | B7: HOG_128_16x16.csv | C7: Knn7 | D7: 5133 | E7: =B7&C7&A7 -> HOG_128_16x16.csvKnn770/30 | F7: =DIVIDE(D7,10000) -> 0.5133
A8: 70/30 | B8: HOG_128_16x16.csv | C8: Knn8 | D8: 5530 | E8: =B8&C8&A8 -> HOG_128_16x16.csvKnn870/30 | F8: =DIVIDE(D8,10000) -> 0.553
A9: 70/30 | B9: HOG_128_16x16.csv | C9: Knn9 | D9: 5108 | E9: =B9&C9&A9 -> HOG_128_16x16.csvKnn970/30 | F9: =DIVIDE(D9,10000) -> 0.5108
A10: 70/30 | B10: HOG_128_16x16.csv | C10: Knn10 | D10: 5336 | E10: =B10&C10&A10 -> HOG_128_16x16.csvKnn1070/30 | F10: =DIVIDE(D10,10000) -> 0.5336
A11: 70/30 | B11: HOG_128_16x16_PCA75.csv | C11: Knn1 | D11: 6202 | E11: =B11&C11&A11 -> HOG_128_16x16_PCA75.csvKnn170/30 | F11: =DIVIDE(D11,10000) -> 0.6202
A12: 70/30 | B12: HOG_128_16x16_PCA75.csv | C12: Knn2 | D12: 6631 | E12: =B12&C12&A12 -> HOG_128_16x16_PCA75.csvKnn270/30 | F12: =DIVIDE(D12,10000) -> 0.6631
... A360: 70/30 | B360: LBP_256_6r_PCA90.csv | C360: Knn10 | D360: 6269 | E360: =B360&C360&A360 -> LBP_256_6r_PCA90.csvKnn1070/30 | F360: =DIVIDE(D360,10000) -> 0.6269

Sheet Dados10Fold
A1: 10Fold | B1: HOG_128_16x16.csv | C1: Knn1 | D1: 5824 | E1: =B1&C1&A1 -> HOG_128_16x16.csvKnn110Fold | F1: =DIVIDE(D1,10000) -> 0.5824
A2: 10Fold | B2: HOG_128_16x16.csv | C2: Knn2 | D2: 6199 | E2: =B2&C2&A2 -> HOG_128_16x16.csvKnn210Fold | F2: =DIVIDE(D2,10000) -> 0.6199
A3: 10Fold | B3: HOG_128_16x16.csv | C3: Knn3 | D3: 5597 | E3: =B3&C3&A3 -> HOG_128_16x16.csvKnn310Fold | F3: =DIVIDE(D3,10000) -> 0.5597
A4: 10Fold | B4: HOG_128_16x16.csv | C4: Knn4 | D4: 6059 | E4: =B4&C4&A4 -> HOG_128_16x16.csvKnn410Fold | F4: =DIVIDE(D4,10000) -> 0.6059
A5: 10Fold | B5: HOG_128_16x16.csv | C5: Knn5 | D5: 5399 | E5: =B5&C5&A5 -> HOG_128_16x16.csvKnn510Fold | F5: =DIVIDE(D5,10000) -> 0.5399
A6: 10Fold | B6: HOG_128_16x16.csv | C6: Knn6 | D6: 5847 | E6: =B6&C6&A6 -> HOG_128_16x16.csvKnn610Fold | F6: =DIVIDE(D6,10000) -> 0.5847
A7: 10Fold | B7: HOG_128_16x16.csv | C7: Knn7 | D7: 5236 | E7: =B7&C7&A7 -> HOG_128_16x16.csvKnn710Fold | F7: =DIVIDE(D7,10000) -> 0.5236
A8: 10Fold | B8: HOG_128_16x16.csv | C8: Knn8 | D8: 5621 | E8: =B8&C8&A8 -> HOG_128_16x16.csvKnn810Fold | F8: =DIVIDE(D8,10000) -> 0.5621
A9: 10Fold | B9: HOG_128_16x16.csv | C9: Knn9 | D9: 5065 | E9: =B9&C9&A9 -> HOG_128_16x16.csvKnn910Fold | F9: =DIVIDE(D9,10000) -> 0.5065
A10: 10Fold | B10: HOG_128_16x16.csv | C10: Knn10 | D10: 5432 | E10: =B10&C10&A10 -> HOG_128_16x16.csvKnn1010Fold | F10: =DIVIDE(D10,10000) -> 0.5432
A11: 10Fold | B11: HOG_128_16x16_PCA75.csv | C11: Knn1 | D11: 6453 | E11: =B11&C11&A11 -> HOG_128_16x16_PCA75.csvKnn110Fold | F11: =DIVIDE(D11,10000) -> 0.6453
A12: 10Fold | B12: HOG_128_16x16_PCA75.csv | C12: Knn2 | D12: 6743 | E12: =B12&C12&A12 -> HOG_128_16x16_PCA75.csvKnn210Fold | F12: =DIVIDE(D12,10000) -> 0.6743
... A360: 10Fold | B360: LBP_256_6r_PCA90.csv | C360: Knn10 | D360: 6250 | E360: =B360&C360&A360 -> LBP_256_6r_PCA90.csvKnn1010Fold | F360: =DIVIDE(D360,10000) -> 0.625
